[CODE](../src/syntax/panic-and-recover.go)

GoLang的内建类型系统捕捉许多编译时错误，但不能检查运行时如数组访问越界或`nil`指针*顺从*（deference）等错误。

Go没有异常机制，程序员不能抛出异常。

在执行过程中，当Go检测到这些错误，将恐慌并停止所有正常操作，在`goroutine`中所有延期函数调用被执行，程序最后记录崩溃日志信息。

该日志信息通常有着充分的资料来分析引发问题的根因，不必重复运行程序，因此这些日志信息总是包含在有关恐慌程序的问题报告中。

`panic`是内建函数，停止普通的控制流程并开始恐慌。

当函数`X`调用`panic`，`X`停止执行，任何`X`中的延期函数调用正常执行，然后`X`返回到主调函数中。

对于主调函数，`X`的行为正如调用`panic`一样。

进程持续出栈（逐层跳出外围函数），直到当前`goroutine`中所有函数都返回，就这此时，程序崩溃。

恐慌可通过直接调用`panic`函数初始化；也可因运行时错误引起，如数组访问越界。

并非所有恐慌都来自运行时。

内建`panic`函数可能被主动调用；它允许任何值作为参数。
一个恐慌通常是当某些“不可能”情况发生时的最佳操作，举个例子，执行到逻辑上不可能发生的情况。

```
fmt.Println("typein 1 for student and 2 for teacher.")
var action int
fmt.Scanln(&action)
switch action {
case 1:
    fmt.Println("student")
case 2:
    fmt.Println("teacher")
default:
    panic(fmt.SPrintf("unknown: %d", action))
}
```

上边的例子，如果输入的不是1或2，程序将会停止执行，进入恐慌。

`recover`是内建函数，它恢复一个陷入恐慌的`goroutine`控制。

`recover`仅在`defer`函数内有用。

在正常执行过程中，调用`recover`将返回`nil`，无任何别的副作用。

如果当前`goroutine`陷入恐慌，调用`recover`将捕捉给到恐慌的值并恢复正常运行。